Workbook
Name AccountNames: [1]Lists!$B$3:$B$2001
Name CDMQRCentralBPAClarityUploadQuarterlies_1: #REF!
Name CDMQRCentralBPAClarityUploadQuarterlies_1: #REF!
Name CDMQRCentralBPAClarityUploadQuarterlies_1: #REF!
Name CDMQRCentralBPAClarityUploadQuarterlies_1: #REF!
Name CDMQRCentralBPAClarityUploadQuarterlies_1: #REF!
Name CDMQRCentralBPAClarityUploadQuarterlies_1: #REF!
Name CDMQRCentralBPAClarityUploadQuarterlies_1: #REF!
Name CDMQRCentralBPAClarityUploadQuarterlies_1: #REF!
Name CDMQRCentralBPAClarityUploadQuarterlies_1: #REF!
Name CDMQRCentralBPAClarityUploadQuarterlies_1: #REF!
Name CDMQRClarityuploadfileQ316.xlsx_1: #REF!
Name CDMQRClarityuploadfileQ316.xlsx_1: #REF!
Name CDMQRClarityuploadfileQ316.xlsx_1: #REF!
Name CDMQRClarityuploadfileQ316.xlsx_1: #REF!
Name CDMQRClarityuploadfileQ316.xlsx_1: #REF!
Name CDMQRClarityuploadfileQ316.xlsx_1: #REF!
Name CDMQRClarityuploadfileQ316.xlsx_1: #REF!
Name CDMQRClarityuploadfileQ316.xlsx_1: #REF!
Name CDMQRClarityuploadfileQ316.xlsx_1: #REF!
Name CDMQRClarityuploadfileQ316.xlsx_2: #REF!
Name CDMQRClarityuploadfileQ316.xlsx_2: #REF!
Name CDMQRClarityuploadfileQ316.xlsx_2: #REF!
Name CDMQRClarityuploadfileQ316.xlsx_2: #REF!
Name CDMQRClarityuploadfileQ316.xlsx_2: #REF!
Name CDMQRClarityuploadfileQ316.xlsx_2: #REF!
Name CDMQRClarityuploadfileQ316.xlsx_2: #REF!
Name CDMQRClarityuploadfileQ316.xlsx_3: #REF!
Name CDMQRClarityuploadfileQ316.xlsx_3: #REF!
Name CDMQRClarityuploadfileQ316.xlsx_3: #REF!
Name CDMQRClarityuploadfileQ316.xlsx_3: #REF!
Name CDMQRClarityuploadfileQ316.xlsx_3: #REF!
Name CDMQRClarityuploadfileQ316.xlsx_3: #REF!
Name CDMQRClarityuploadfileQ316.xlsx_4: #REF!
Name CDMQRClarityuploadfileQ316.xlsx_4: #REF!
Name CDMQRClarityuploadfileQ316.xlsx_4: #REF!
Name CDMQRClarityuploadfileQ316.xlsx_4: #REF!
Name CDMQRClarityuploadfileQ316.xlsx_4: #REF!
Name CDMQRClarityuploadfileQ316.xlsx_4: #REF!
Name CQtr: #REF!
Name CQtr: #REF!
Name CQtr: #REF!
Name Entity: [1]Lists!$F$3:$F$501
Name OLE_LINK1: 'L&A by product'!#REF!
Name OLE_LINK1: 'L&A by stage'!$A$2
Name OLE_LINK1: 'Margins and balances'!$A$2
Name PPPPPPPQtr: #REF!
Name PPPPPPPQtr: #REF!
Name PPPPPPPQtr: #REF!
Name PPPPPPPQtr: #REF!
Name PPPPPPPQtr: #REF!
Name PPPPPPQtr: #REF!
Name PPPPPPQtr: #REF!
Name PPPPPPQtr: #REF!
Name PPPPPPQtr: #REF!
Name PPPPPPQtr: #REF!
Name PPPPPQtr: #REF!
Name PPPPPQtr: #REF!
Name PPPPPQtr: #REF!
Name PPPPPQtr: #REF!

Sheet YTD Consolidation check 
B1: =CQtr&" YTD" -> #REF! | C1: Group | G1: BUK | J1: CIB | M1: CCP | P1: BI | S1: HO | W1: Cast to Group | Z1: Cast to Core | AC1: CIB+CCP=BI | AF1: Cast to Core
C2: =CQtr&" YTD" -> #REF! | D2: =PPPPQtr&" YTD" -> #REF! | G2: =CQtr&" YTD" -> #REF! | H2: =PPPPQtr&" YTD" -> #REF! | J2: =CQtr&" YTD" -> #REF! | K2: =PPPPQtr&" YTD" -> #REF! | M2: =CQtr&" YTD" -> #REF! | N2: =PPPPQtr&" YTD" -> #REF! | P2: =CQtr&" YTD" -> #REF! | Q2: =PPPPQtr&" YTD" -> #REF! | S2: =CQtr&" YTD" -> #REF! | T2: =PPPPQtr&" YTD" -> #REF! | W2: =CQtr&" YTD" -> #REF! | Y2: =PPPPQtr&" YTD" -> #REF! | AC2: =CQtr&" YTD" -> #REF! | AE2: =PPPPQtr&" YTD" -> #REF!
B3: Total income | C3: ='Group PH'!C4 -> 6283 | D3: ='Group PH'!D4 -> 5252 | G3: ='Barclays UK YTD'!C7 -> 7353 | H3: ='Barclays UK YTD'!D7 -> 7383 | J3: ='Barclays International YTD'!C62 -> 10231 | K3: ='Barclays International YTD'!D62 -> 9765 | M3: ='Barclays International YTD'!C102 -> 4444 | N3: ='Barclays International YTD'!D102 -> 4261 | P3: ='Barclays International YTD'!C8 -> 14675 | Q3: ='Barclays International YTD'!D8 -> 14026 | S3: ='Head Office YTD'!C7 -> -396 | T3: ='Head Office YTD'!D7 -> -273 | W3: =ROUND(G3,0)+ROUND(S3,0)+ROUND(P3,0)-ROUND(C3,0) -> 15349 | Y3: =ROUND(H3,0)+ROUND(T3,0)+ROUND(Q3,0)-ROUND(D3,0) -> 15884 | Z3: =ROUND(H3,0)+ROUND(T3,0)+ROUND(Q3,0)-ROUND(#REF!,0) -> #REF! | AC3: =P3-J3-M3 -> -8.1854523e-12 | AE3: =Q3-K3-N3 -> 0 | AF3: =ROUND(N3,0)+ROUND(Z3,0)+ROUND(W3,0)-ROUND(#REF!,0) -> #REF!
B4: Credit impairment charges and other provisions | C4: ='Group PH'!C5 -> -2115 | D4: ='Group PH'!D5 -> -448 | G4: ='Barclays UK YTD'!C8 -> -712 | H4: ='Barclays UK YTD'!D8 -> -826 | J4: ='Barclays International YTD'!C63 -> -157 | K4: ='Barclays International YTD'!D63 -> 150 | M4: ='Barclays International YTD'!C103 -> -1016 | N4: ='Barclays International YTD'!D103 -> -808 | P4: ='Barclays International YTD'!C9 -> -1173 | Q4: ='Barclays International YTD'!D9 -> -658 | S4: ='Head Office YTD'!C8 -> -27 | T4: ='Head Office YTD'!D8 -> 16 | W4: =ROUND(G4,0)+ROUND(S4,0)+ROUND(P4,0)-ROUND(C4,0) -> 203 | Y4: =ROUND(H4,0)+ROUND(T4,0)+ROUND(Q4,0)-ROUND(D4,0) -> -1020 | Z4: =ROUND(H4,0)+ROUND(T4,0)+ROUND(Q4,0)-ROUND(#REF!,0) -> #REF! | AC4: =P4-J4-M4 -> 0 | AE4: =Q4-K4-N4 -> 0 | AF4: =ROUND(N4,0)+ROUND(Z4,0)+ROUND(W4,0)-ROUND(#REF!,0) -> #REF!
B5: Net operating income | C5: ='Group PH'!C6 -> 4168 | D5: ='Group PH'!D6 -> 4804 | G5: ='Barclays UK YTD'!C9 -> 6641 | H5: ='Barclays UK YTD'!D9 -> 6557 | J5: ='Barclays International YTD'!C64 -> 10074 | K5: ='Barclays International YTD'!D64 -> 9915 | M5: ='Barclays International YTD'!C104 -> 3428 | N5: ='Barclays International YTD'!D104 -> 3453 | P5: ='Barclays International YTD'!C10 -> 13502 | Q5: ='Barclays International YTD'!D10 -> 13368 | S5: ='Head Office YTD'!C9 -> -423 | T5: ='Head Office YTD'!D9 -> -257 | W5: =ROUND(G5,0)+ROUND(S5,0)+ROUND(P5,0)-ROUND(C5,0) -> 15552 | Y5: =ROUND(H5,0)+ROUND(T5,0)+ROUND(Q5,0)-ROUND(D5,0) -> 14864 | Z5: =ROUND(H5,0)+ROUND(T5,0)+ROUND(Q5,0)-ROUND(#REF!,0) -> #REF! | AC5: =P5-J5-M5 -> 0 | AE5: =Q5-K5-N5 -> 0 | AF5: =ROUND(N5,0)+ROUND(Z5,0)+ROUND(W5,0)-ROUND(#REF!,0) -> #REF!
B6: Operating expenses | C6: ='Group PH'!C7 -> -3253 | D6: ='Group PH'!D7 -> -3257 | G6: ='Barclays UK YTD'!C10 -> -3995.6945 | H6: ='Barclays UK YTD'!D10 -> -4075 | J6: ='Barclays International YTD'!C65 -> -6882 | K6: ='Barclays International YTD'!D65 -> -7093 | M6: ='Barclays International YTD'!C105 -> -2281 | N6: ='Barclays International YTD'!D105 -> -2231 | P6: ='Barclays International YTD'!C11 -> -9162.8284 | Q6: ='Barclays International YTD'!D11 -> -9324 | S6: ='Head Office YTD'!C10 -> -200 | T6: ='Head Office YTD'!D10 -> -228 | W6: =ROUND(G6,0)+ROUND(S6,0)+ROUND(P6,0)-ROUND(C6,0) -> -10106 | Y6: =ROUND(H6,0)+ROUND(T6,0)+ROUND(Q6,0)-ROUND(D6,0) -> -10370 | Z6: =ROUND(H6,0)+ROUND(T6,0)+ROUND(Q6,0)-ROUND(#REF!,0) -> #REF! | AC6: =P6-J6-M6 -> 0.17155109 | AE6: =Q6-K6-N6 -> 0 | AF6: =ROUND(N6,0)+ROUND(Z6,0)+ROUND(W6,0)-ROUND(#REF!,0) -> #REF! | AH6: Bank levy
B7: Bank Levy | C7: ='Group PH'!#REF! -> #REF! | D7: ='Group PH'!#REF! -> #REF! | G7: ='Barclays UK YTD'!C11 -> -41 | H7: ='Barclays UK YTD'!D11 -> -46 | J7: ='Barclays International YTD'!C66 -> -156 | K7: ='Barclays International YTD'!D66 -> -188 | M7: ='Barclays International YTD'!C106 -> -18.4 | N7: ='Barclays International YTD'!D106 -> -22 | P7: ='Barclays International YTD'!C12 -> -174.4 | Q7: ='Barclays International YTD'!D12 -> -210 | S7: ='Head Office YTD'!C11 -> -11 | T7: ='Head Office YTD'!D11 -> -13 | W7: =ROUND(G7,0)+ROUND(S7,0)+ROUND(P7,0)-ROUND(C7,0) -> #REF! | Y7: =ROUND(H7,0)+ROUND(T7,0)+ROUND(Q7,0)-ROUND(D7,0) -> #REF! | AC7: =P7-J7-M7 -> 3.1974423e-14 | AE7: =Q7-K7-N7 -> 0
B8: Litigation and conduct | C8: ='Group PH'!C8 -> -10.340854 | D8: ='Group PH'!D8 -> -61 | G8: ='Barclays UK YTD'!C13 -> -1582.3055 | H8: ='Barclays UK YTD'!D13 -> -483 | J8: ='Barclays International YTD'!C68 -> -109.36277 | K8: ='Barclays International YTD'!D68 -> -68 | M8: ='Barclays International YTD'!C108 -> -7.4087847 | N8: ='Barclays International YTD'!D108 -> -59 | P8: ='Barclays International YTD'!C14 -> -115.77155 | Q8: ='Barclays International YTD'!D14 -> -127 | S8: ='Head Office YTD'!C14 -> -151.39434 | T8: ='Head Office YTD'!D14 -> -1597 | W8: =ROUND(G8,0)+ROUND(S8,0)+ROUND(P8,0)-ROUND(C8,0) -> -1839 | Y8: =ROUND(H8,0)+ROUND(T8,0)+ROUND(Q8,0)-ROUND(D8,0) -> -2146 | Z8: =ROUND(H8,0)+ROUND(T8,0)+ROUND(Q8,0)-ROUND(#REF!,0) -> #REF! | AC8: =ROUND(P8,0)-ROUND(J8,0)-ROUND(M8,0) -> 0 | AE8: =Q8-K8-N8 -> 0 | AF8: =ROUND(N8,0)+ROUND(Z8,0)+ROUND(W8,0)-ROUND(#REF!,0) -> #REF!
B9: Total operating expenses | C9: ='Group PH'!C9 -> -3263 | D9: ='Group PH'!D9 -> -3318 | G9: ='Barclays UK YTD'!C14 -> -5619 | H9: ='Barclays UK YTD'!D14 -> -4604 | J9: ='Barclays International YTD'!C69 -> -7147 | K9: ='Barclays International YTD'!D69 -> -7349 | M9: ='Barclays International YTD'!C109 -> -2306 | N9: ='Barclays International YTD'!D109 -> -2312 | P9: ='Barclays International YTD'!C15 -> -9453 | Q9: ='Barclays International YTD'!D15 -> -9661 | S9: ='Head Office YTD'!C15 -> -362 | T9: ='Head Office YTD'!D15 -> -1978 | W9: =ROUND(G9,0)+ROUND(S9,0)+ROUND(P9,0)-ROUND(C9,0) -> -12171 | Y9: =ROUND(H9,0)+ROUND(T9,0)+ROUND(Q9,0)-ROUND(D9,0) -> -12925 | Z9: =ROUND(H9,0)+ROUND(T9,0)+ROUND(Q9,0)-ROUND(#REF!,0) -> #REF! | AC9: =P9-J9-M9 -> 0 | AE9: =Q9-K9-N9 -> 0 | AF9: =ROUND(N9,0)+ROUND(Z9,0)+ROUND(W9,0)-ROUND(#REF!,0) -> #REF!
B10: Other net (expenses)/income | C10: ='Group PH'!C10 -> 8 | D10: ='Group PH'!D10 -> -3 | G10: ='Barclays UK YTD'!C15 -> - | H10: ='Barclays UK YTD'!D15 -> 3 | J10: ='Barclays International YTD'!C70 -> 28 | K10: ='Barclays International YTD'!D70 -> 27 | M10: ='Barclays International YTD'!C110 -> 41 | N10: ='Barclays International YTD'!D110 -> 41 | P10: ='Barclays International YTD'!C16 -> 69 | Q10: ='Barclays International YTD'!D16 -> 68 | S10: ='Head Office YTD'!C16 -> 2 | T10: ='Head Office YTD'!D16 -> -2 | W10: =ROUND(G10,0)+ROUND(S10,0)+ROUND(P10,0)-ROUND(C10,0) -> #VALUE! | Y10: =ROUND(H10,0)+ROUND(T10,0)+ROUND(Q10,0)-ROUND(D10,0) -> 72 | Z10: =ROUND(H10,0)+ROUND(T10,0)+ROUND(Q10,0)-ROUND(#REF!,0) -> #REF! | AC10: =P10-J10-M10 -> 0 | AE10: =Q10-K10-N10 -> 0 | AF10: =ROUND(N10,0)+ROUND(Z10,0)+ROUND(W10,0)-ROUND(#REF!,0) -> #REF!
B11: Profit/(loss) before tax | C11: ='Group PH'!C11 -> 913 | D11: ='Group PH'!D11 -> 1483 | G11: ='Barclays UK YTD'!C16 -> 1022 | H11: ='Barclays UK YTD'!D16 -> 1956 | J11: ='Barclays International YTD'!C71 -> 2955 | K11: ='Barclays International YTD'!D71 -> 2593 | M11: ='Barclays International YTD'!C111 -> 1163 | N11: ='Barclays International YTD'!D111 -> 1182 | P11: ='Barclays International YTD'!C17 -> 4118 | Q11: ='Barclays International YTD'!D17 -> 3775 | S11: ='Head Office YTD'!C17 -> -783 | T11: ='Head Office YTD'!D17 -> -2237 | W11: =ROUND(G11,0)+ROUND(S11,0)+ROUND(P11,0)-ROUND(C11,0) -> 3444 | Y11: =ROUND(H11,0)+ROUND(T11,0)+ROUND(Q11,0)-ROUND(D11,0) -> 2011 | Z11: =ROUND(H11,0)+ROUND(T11,0)+ROUND(Q11,0)-ROUND(#REF!,0) -> #REF! | AC11: =P11-J11-M11 -> 0 | AE11: =Q11-K11-N11 -> 0 | AF11: =ROUND(N11,0)+ROUND(Z11,0)+ROUND(W11,0)-ROUND(#REF!,0) -> #REF!
B12: Attributable profit/(loss)1 | C12: ='Group PH'!C16 -> 605 | D12: ='Group PH'!D16 -> 1038 | G12: ='Barclays UK YTD'!C17 -> 281 | H12: ='Barclays UK YTD'!D17 -> 1198 | J12: ='Barclays International YTD'!C72 -> 1980 | K12: ='Barclays International YTD'!D72 -> 1781 | M12: ='Barclays International YTD'!C112 -> 836 | N12: ='Barclays International YTD'!D112 -> 818 | P12: ='Barclays International YTD'!C18 -> 2816 | Q12: ='Barclays International YTD'!D18 -> 2599 | S12: ='Head Office YTD'!C18 -> -636 | T12: ='Head Office YTD'!D18 -> -2200 | W12: =ROUND(G12,0)+ROUND(S12,0)+ROUND(P12,0)-ROUND(C12,0) -> 1856 | Y12: =ROUND(H12,0)+ROUND(T12,0)+ROUND(Q12,0)-ROUND(D12,0) -> 559 | Z12: =ROUND(H12,0)+ROUND(T12,0)+ROUND(Q12,0)-ROUND(#REF!,0) -> #REF! | AC12: =P12-J12-M12 -> 1.0231815e-12 | AE12: =Q12-K12-N12 -> 0 | AF12: =ROUND(N12,0)+ROUND(Z12,0)+ROUND(W12,0)-ROUND(#REF!,0) -> #REF!
B14: Average tangible shareholders' equity (£bn) | C14: ='Group PH'!C20 -> 46994.626 | D14: ='Group PH'!D20 -> 45200 | G14: ='Barclays UK YTD'!C36 -> 10333.198 | H14: ='Barclays UK YTD'!D36 -> 10000 | J14: ='Barclays International YTD'!C88 -> 25886.815 | K14: ='Barclays International YTD'!D88 -> 26000 | M14: ='Barclays International YTD'!C130 -> 5281.7143 | N14: ='Barclays International YTD'!D130 -> 5000 | P14: ='Barclays International YTD'!C36 -> 31168.529 | Q14: ='Barclays International YTD'!D36 -> 31000 | S14: ='Head Office YTD'!C26 -> 5056.3352 | T14: ='Head Office YTD'!D26 -> 3100 | W14: =ROUND(G14,0)+ROUND(S14,0)+ROUND(P14,0)-ROUND(C14,0) -> -437 | Y14: =ROUND(H14,0)+ROUND(T14,0)+ROUND(Q14,0)-ROUND(D14,0) -> -1100 | Z14: =ROUND(H14,-2)+ROUND(T14,-2)+ROUND(Q14,-2)-ROUND(#REF!,-2) -> #REF! | AC14: =P14-J14-M14 -> 0 | AE14: =Q14-K14-N14 -> 0 | AF14: =ROUND(N14,-2)+ROUND(Z14,-2)+ROUND(W14,-2)-ROUND(#REF!,-2) -> #REF!
B15: Basic earnings/(loss) per share | C15: ='Group PH'!C23 -> 3.5015357 | D15: ='Group PH'!D23 -> 6.1
B17: Profit/(loss) before tax ex L&C | C17: ='Group PH'!C26 -> 923.34085 | D17: ='Group PH'!D26 -> 1544 | G17: ='Barclays UK YTD'!C42 -> 2604.3055 | H17: ='Barclays UK YTD'!D42 -> 2439 | J17: ='Barclays International YTD'!C92 -> 3064.3628 | K17: ='Barclays International YTD'!D92 -> 2661 | M17: ='Barclays International YTD'!C135 -> 1170.4088 | N17: ='Barclays International YTD'!D135 -> 1241 | P17: ='Barclays International YTD'!C42 -> 4233.7716 | Q17: ='Barclays International YTD'!D42 -> 3902 | S17: ='Head Office YTD'!C29 -> -631.60566 | T17: ='Head Office YTD'!D29 -> -640 | W17: =ROUND(G17,0)+ROUND(S17,0)+ROUND(P17,0)-ROUND(C17,0) -> 5283 | Y17: =ROUND(H17,0)+ROUND(T17,0)+ROUND(Q17,0)-ROUND(D17,0) -> 4157 | AC17: =ROUND(P17,0)-ROUND(J17,0)-ROUND(M17,0) -> 0 | AE17: =Q17-K17-N17 -> 0
B18: Attributable profit/(loss) ex L&C | C18: ='Group PH'!C27 -> 604.40094 | D18: ='Group PH'!D27 -> 1084 | G18: ='Barclays UK YTD'!C43 -> 1813.076 | H18: ='Barclays UK YTD'!D43 -> 1670 | J18: ='Barclays International YTD'!C93 -> 2063.5163 | K18: ='Barclays International YTD'!D93 -> 1843 | M18: ='Barclays International YTD'!C136 -> 841.52103 | N18: ='Barclays International YTD'!D136 -> 862 | P18: ='Barclays International YTD'!C43 -> 2906.0373 | Q18: ='Barclays International YTD'!D43 -> 2705 | S18: ='Head Office YTD'!C30 -> -524.84075 | T18: ='Head Office YTD'!D30 -> -642 | W18: =ROUND(G18,0)+ROUND(S18,0)+ROUND(P18,0)-ROUND(C18,0) -> 3590 | Y18: =ROUND(H18,0)+ROUND(T18,0)+ROUND(Q18,0)-ROUND(D18,0) -> 2649 | AC18: =ROUND(P18,0)-ROUND(J18,0)-ROUND(M18,0) -> 0 | AE18: =Q18-K18-N18 -> 0
B19: Post tax L&C impact | C19: ='CYYTD performance measures excl'!G21 -> 1733 | D19: ='PYYTD performance measures'!G21 -> 2136 | G19: ='CYYTD performance measures excl'!B21 -> 1532 | H19: ='PYYTD performance measures'!B21 -> 472 | J19: ='CYYTD performance measures excl'!C21 -> 84 | K19: ='PYYTD performance measures'!C21 -> 62 | M19: ='CYYTD performance measures excl'!D21 -> 6 | N19: ='PYYTD performance measures'!D21 -> 44 | P19: ='CYYTD performance measures excl'!E21 -> 90 | Q19: ='PYYTD performance measures'!E21 -> 106 | S19: ='CYYTD performance measures excl'!F21 -> 111 | T19: ='PYYTD performance measures'!F21 -> 1558 | W19: =ROUND(G19,0)+ROUND(S19,0)+ROUND(P19,0)-ROUND(C19,0) -> 0 | Y19: =ROUND(H19,0)+ROUND(T19,0)+ROUND(Q19,0)-ROUND(D19,0) -> 0 | AC19: =P19-J19-M19 -> 0 | AE19: =Q19-K19-N19 -> 0
B21: Total assets | C21: ='Group Qrtly'!C38 -> 1444297 | D21: ='Group Qrtly'!H38 -> 1193543 | G21: ='Barclays UK YTD'!C21 -> 257776 | H21: ='Barclays UK YTD'!D21 -> 249700 | J21: ='Barclays International YTD'!C81 -> 795600 | K21: ='Barclays International YTD'!D81 -> 790500 | M21: ='Barclays International YTD'!C116 -> 65800 | N21: ='Barclays International YTD'!D116 -> 71600 | P21: ='Barclays International YTD'!C27 -> 861400 | Q21: ='Barclays International YTD'!D27 -> 862100 | S21: ='Head Office YTD'!C21 -> 21040 | T21: ='Head Office YTD'!D21 -> 21500 | W21: =ROUND(G21,-2)+ROUND(S21,-2)+ROUND(P21,-2)-ROUND(C21,-2) -> -304100 | Y21: =ROUND(H21,-2)+ROUND(T21,-2)+ROUND(Q21,-2)-ROUND(D21,-2) -> -60200 | Z21: =ROUND(H21,-3)+ROUND(T21,-3)+ROUND(Q21,-3)-ROUND(#REF!,-3) -> #REF! | AC21: =P21-J21-M21 -> 0 | AE21: =Q21-K21-N21 -> 0 | AF21: =ROUND(N21,-3)+ROUND(Z21,-3)+ROUND(W21,-3)-ROUND(#REF!,-3) -> #REF!
B22: Risk weighted assets | C22: ='Group PH'!C37 -> 325631 | D22: ='Group PH'!D37 -> 295131.09 | G22: ='Barclays UK YTD'!C24 -> 74900.809 | H22: ='Barclays UK YTD'!D24 -> 75200 | J22: ='Barclays International YTD'!C84 -> 171452.99 | K22: ='Barclays International YTD'!D84 -> 170900 | M22: ='Barclays International YTD'!C118 -> 37690.31 | N22: ='Barclays International YTD'!D118 -> 39800 | P22: ='Barclays International YTD'!C31 -> 209243.3 | Q22: ='Barclays International YTD'!D31 -> 210741 | S22: ='Head Office YTD'!C22 -> 10986.984 | T22: ='Head Office YTD'!D22 -> 26000 | W22: =ROUND(G22,-2)+ROUND(S22,-2)+ROUND(P22,-2)-ROUND(C22,-2) -> -30500 | Y22: =ROUND(H22,-2)+ROUND(T22,-2)+ROUND(Q22,-2)-ROUND(D22,-2) -> 16800 | AC22: =P22-J22-M22 -> 100 | AE22: =Q22-K22-N22 -> 41
B23: Average UK leverage exposure | C23: ='Group PH'!#REF! -> #REF! | D23: ='Group PH'!#REF! -> #REF! | Z23: =ROUND(H23,-3)+ROUND(T23,-3)+ROUND(Q23,-3)-ROUND(#REF!,-3) -> #REF! | AF23: =ROUND(N23,-3)+ROUND(Z23,-3)+ROUND(W23,-3)-ROUND(#REF!,-3) -> #REF!
B29: Quarterly pages
B31: =CQtr&" YTD" -> #REF! | C31: Group | G31: BUK | J31: CIB | M31: CCP | P31: BI | S31: HO | W31: Cast to Group | Z31: Cast to Core | AC31: CIB+CCP=BI | AF31: Cast to Core
C32: =CQtr&" YTD" -> #REF! | D32: =PPPPQtr&" YTD" -> #REF! | G32: =CQtr&" YTD" -> #REF! | H32: =PPPPQtr&" YTD" -> #REF! | J32: =CQtr&" YTD" -> #REF! | K32: =PPPPQtr&" YTD" -> #REF! | M32: =CQtr&" YTD" -> #REF! | N32: =PPPPQtr&" YTD" -> #REF! | P32: =CQtr&" YTD" -> #REF! | Q32: =PPPPQtr&" YTD" -> #REF! | S32: =CQtr&" YTD" -> #REF! | T32: =PPPPQtr&" YTD" -> #REF! | W32: =CQtr&" YTD" -> #REF! | Y32: =PPPPQtr&" YTD" -> #REF!
B33: Total income | C33: =ROUND('Group Qrtly'!C6,0)+ROUND('Group Qrtly'!E6,0)+ROUND('Group Qrtly'!F6,0)+ROUND('Group Qrtly'!G6,0) -> 22663 | D33: =ROUND('Group Qrtly'!H6,0)+ROUND('Group Qrtly'!J6,0)+ROUND('Group Qrtly'!K6,0)+ROUND('Group Qrtly'!L6,0) -> 21030 | G33: =ROUND('Barclays UK Qrtly'!C7,0)+ROUND('Barclays UK Qrtly'!E7,0)+ROUND('Barclays UK Qrtly'!F7,0)+ROUND('Barclays UK Qrtly'!G7,0) -> 7280 | H33: =ROUND('Barclays UK Qrtly'!H7,0)+ROUND('Barclays UK Qrtly'!J7,0)+ROUND('Barclays UK Qrtly'!K7,0)+ROUND('Barclays UK Qrtly'!L7,0) -> 7372 | J33: =ROUND('Barclays International Qrtly'!C64,0)+ROUND('Barclays International Qrtly'!E64,0)+ROUND('Barclays International Qrtly'!F64,0)+ROUND('Barclays International Qrtly'!G64,0) -> 11343 | K33: =ROUND('Barclays International Qrtly'!H64,0)+ROUND('Barclays International Qrtly'!J64,0)+ROUND('Barclays International Qrtly'!K64,0)+ROUND('Barclays International Qrtly'!L64,0) -> 9471 | M33: =ROUND('Barclays International Qrtly'!C105,0)+ROUND('Barclays International Qrtly'!E105,0)+ROUND('Barclays International Qrtly'!F105,0)+ROUND('Barclays International Qrtly'!G105,0) -> 4406 | N33: =ROUND('Barclays International Qrtly'!H105,0)+ROUND('Barclays International Qrtly'!J105,0)+ROUND('Barclays International Qrtly'!K105,0)+ROUND('Barclays International Qrtly'!L105,0) -> 4317 | P33: =ROUND('Barclays International Qrtly'!C8,0)+ROUND('Barclays International Qrtly'!E8,0)+ROUND('Barclays International Qrtly'!F8,0)+ROUND('Barclays International Qrtly'!G8,0) -> 15749 | Q33: =ROUND('Barclays International Qrtly'!H8,0)+ROUND('Barclays International Qrtly'!J8,0)+ROUND('Barclays International Qrtly'!K8,0)+ROUND('Barclays International Qrtly'!L8,0) -> 13788 | S33: =ROUND('Head Office Qrtly'!C7,0)+ROUND('Head Office Qrtly'!E7,0)+ROUND('Head Office Qrtly'!F7,0)+ROUND('Head Office Qrtly'!G7,0) -> -366 | T33: =ROUND('Head Office Qrtly'!H7,0)+ROUND('Head Office Qrtly'!J7,0)+ROUND('Head Office Qrtly'!K7,0)+ROUND('Head Office Qrtly'!L7,0) -> -130 | W33: =ROUND(G33,0)+ROUND(S33,0)+ROUND(P33,0)-ROUND(C33,0) -> 0 | Y33: =ROUND(H33,0)+ROUND(T33,0)+ROUND(Q33,0)-ROUND(D33,0) -> 0 | Z33: =ROUND(H33,0)+ROUND(T33,0)+ROUND(Q33,0)-ROUND(#REF!,0) -> #REF! | AC33: =P33-J33-M33 -> 0 | AE33: =Q33-K33-N33 -> 0 | AF33: =ROUND(N33,0)+ROUND(Z33,0)+ROUND(W33,0)-ROUND(#REF!,0) -> #REF!
B34: Credit impairment charges and other provisions | C34: =ROUND('Group Qrtly'!C7,0)+ROUND('Group Qrtly'!E7,0)+ROUND('Group Qrtly'!F7,0)+ROUND('Group Qrtly'!G7,0) -> -3579 | D34: =ROUND('Group Qrtly'!H7,0)+ROUND('Group Qrtly'!J7,0)+ROUND('Group Qrtly'!K7,0)+ROUND('Group Qrtly'!L7,0) -> -1628 | G34: =ROUND('Barclays UK Qrtly'!C8,0)+ROUND('Barclays UK Qrtly'!E8,0)+ROUND('Barclays UK Qrtly'!F8,0)+ROUND('Barclays UK Qrtly'!G8,0) -> -1002 | H34: =ROUND('Barclays UK Qrtly'!H8,0)+ROUND('Barclays UK Qrtly'!J8,0)+ROUND('Barclays UK Qrtly'!K8,0)+ROUND('Barclays UK Qrtly'!L8,0) -> -816 | J34: =ROUND('Barclays International Qrtly'!C65,0)+ROUND('Barclays International Qrtly'!E65,0)+ROUND('Barclays International Qrtly'!F65,0)+ROUND('Barclays International Qrtly'!G65,0) -> -829 | K34: =ROUND('Barclays International Qrtly'!H65,0)+ROUND('Barclays International Qrtly'!J65,0)+ROUND('Barclays International Qrtly'!K65,0)+ROUND('Barclays International Qrtly'!L65,0) -> -61 | M34: =ROUND('Barclays International Qrtly'!C106,0)+ROUND('Barclays International Qrtly'!E106,0)+ROUND('Barclays International Qrtly'!F106,0)+ROUND('Barclays International Qrtly'!G106,0) -> -1708 | N34: =ROUND('Barclays International Qrtly'!H106,0)+ROUND('Barclays International Qrtly'!J106,0)+ROUND('Barclays International Qrtly'!K106,0)+ROUND('Barclays International Qrtly'!L106,0) -> -749 | P34: =ROUND('Barclays International Qrtly'!C9,0)+ROUND('Barclays International Qrtly'!E9,0)+ROUND('Barclays International Qrtly'!F9,0)+ROUND('Barclays International Qrtly'!G9,0) -> -2537 | Q34: =ROUND('Barclays International Qrtly'!H9,0)+ROUND('Barclays International Qrtly'!J9,0)+ROUND('Barclays International Qrtly'!K9,0)+ROUND('Barclays International Qrtly'!L9,0) -> -810 | S34: =ROUND('Head Office Qrtly'!C8,0)+ROUND('Head Office Qrtly'!E8,0)+ROUND('Head Office Qrtly'!F8,0)+ROUND('Head Office Qrtly'!G8,0) -> -40 | T34: =ROUND('Head Office Qrtly'!H8,0)+ROUND('Head Office Qrtly'!J8,0)+ROUND('Head Office Qrtly'!K8,0)+ROUND('Head Office Qrtly'!L8,0) -> -2 | W34: =ROUND(G34,0)+ROUND(S34,0)+ROUND(P34,0)-ROUND(C34,0) -> 0 | Y34: =ROUND(H34,0)+ROUND(T34,0)+ROUND(Q34,0)-ROUND(D34,0) -> 0 | Z34: =ROUND(H34,0)+ROUND(T34,0)+ROUND(Q34,0)-ROUND(#REF!,0) -> #REF! | AC34: =P34-J34-M34 -> 0 | AE34: =Q34-K34-N34 -> 0 | AF34: =ROUND(N34,0)+ROUND(Z34,0)+ROUND(W34,0)-ROUND(#REF!,0) -> #REF!
B35: Net operating income | C35: =ROUND('Group Qrtly'!C8,0)+ROUND('Group Qrtly'!E8,0)+ROUND('Group Qrtly'!F8,0)+ROUND('Group Qrtly'!G8,0) -> 19084 | D35: =ROUND('Group Qrtly'!H8,0)+ROUND('Group Qrtly'!J8,0)+ROUND('Group Qrtly'!K8,0)+ROUND('Group Qrtly'!L8,0) -> 19402 | G35: =ROUND('Barclays UK Qrtly'!C9,0)+ROUND('Barclays UK Qrtly'!E9,0)+ROUND('Barclays UK Qrtly'!F9,0)+ROUND('Barclays UK Qrtly'!G9,0) -> 6278 | H35: =ROUND('Barclays UK Qrtly'!H9,0)+ROUND('Barclays UK Qrtly'!J9,0)+ROUND('Barclays UK Qrtly'!K9,0)+ROUND('Barclays UK Qrtly'!L9,0) -> 6556 | J35: =ROUND('Barclays International Qrtly'!C66,0)+ROUND('Barclays International Qrtly'!E66,0)+ROUND('Barclays International Qrtly'!F66,0)+ROUND('Barclays International Qrtly'!G66,0) -> 10514 | K35: =ROUND('Barclays International Qrtly'!H66,0)+ROUND('Barclays International Qrtly'!J66,0)+ROUND('Barclays International Qrtly'!K66,0)+ROUND('Barclays International Qrtly'!L66,0) -> 9410 | M35: =ROUND('Barclays International Qrtly'!C107,0)+ROUND('Barclays International Qrtly'!E107,0)+ROUND('Barclays International Qrtly'!F107,0)+ROUND('Barclays International Qrtly'!G107,0) -> 2698 | N35: =ROUND('Barclays International Qrtly'!H107,0)+ROUND('Barclays International Qrtly'!J107,0)+ROUND('Barclays International Qrtly'!K107,0)+ROUND('Barclays International Qrtly'!L107,0) -> 3568 | P35: =ROUND('Barclays International Qrtly'!C10,0)+ROUND('Barclays International Qrtly'!E10,0)+ROUND('Barclays International Qrtly'!F10,0)+ROUND('Barclays International Qrtly'!G10,0) -> 13212 | Q35: =ROUND('Barclays International Qrtly'!H10,0)+ROUND('Barclays International Qrtly'!J10,0)+ROUND('Barclays International Qrtly'!K10,0)+ROUND('Barclays International Qrtly'!L10,0) -> 12978 | S35: =ROUND('Head Office Qrtly'!C9,0)+ROUND('Head Office Qrtly'!E9,0)+ROUND('Head Office Qrtly'!F9,0)+ROUND('Head Office Qrtly'!G9,0) -> -406 | T35: =ROUND('Head Office Qrtly'!H9,0)+ROUND('Head Office Qrtly'!J9,0)+ROUND('Head Office Qrtly'!K9,0)+ROUND('Head Office Qrtly'!L9,0) -> -132 | W35: =ROUND(G35,0)+ROUND(S35,0)+ROUND(P35,0)-ROUND(C35,0) -> 0 | Y35: =ROUND(H35,0)+ROUND(T35,0)+ROUND(Q35,0)-ROUND(D35,0) -> 0 | Z35: =ROUND(H35,0)+ROUND(T35,0)+ROUND(Q35,0)-ROUND(#REF!,0) -> #REF! | AC35: =P35-J35-M35 -> 0 | AE35: =Q35-K35-N35 -> 0 | AF35: =ROUND(N35,0)+ROUND(Z35,0)+ROUND(W35,0)-ROUND(#REF!,0) -> #REF!
B36: Operating costs | C36: =ROUND('Group Qrtly'!C9,0)+ROUND('Group Qrtly'!E9,0)+ROUND('Group Qrtly'!F9,0)+ROUND('Group Qrtly'!G9,0) -> -13355 | D36: =ROUND('Group Qrtly'!H9,0)+ROUND('Group Qrtly'!J9,0)+ROUND('Group Qrtly'!K9,0)+ROUND('Group Qrtly'!L9,0) -> -13520 | G36: =ROUND('Barclays UK Qrtly'!C10,0)+ROUND('Barclays UK Qrtly'!E10,0)+ROUND('Barclays UK Qrtly'!F10,0)+ROUND('Barclays UK Qrtly'!G10,0) -> -4020 | H36: =ROUND('Barclays UK Qrtly'!H10,0)+ROUND('Barclays UK Qrtly'!J10,0)+ROUND('Barclays UK Qrtly'!K10,0)+ROUND('Barclays UK Qrtly'!L10,0) -> -4069 | J36: =ROUND('Barclays International Qrtly'!C67,0)+ROUND('Barclays International Qrtly'!E67,0)+ROUND('Barclays International Qrtly'!F67,0)+ROUND('Barclays International Qrtly'!G67,0) -> -6953 | K36: =ROUND('Barclays International Qrtly'!H67,0)+ROUND('Barclays International Qrtly'!J67,0)+ROUND('Barclays International Qrtly'!K67,0)+ROUND('Barclays International Qrtly'!L67,0) -> -6939 | M36: =ROUND('Barclays International Qrtly'!C108,0)+ROUND('Barclays International Qrtly'!E108,0)+ROUND('Barclays International Qrtly'!F108,0)+ROUND('Barclays International Qrtly'!G108,0) -> -2223 | N36: =ROUND('Barclays International Qrtly'!H108,0)+ROUND('Barclays International Qrtly'!J108,0)+ROUND('Barclays International Qrtly'!K108,0)+ROUND('Barclays International Qrtly'!L108,0) -> -2291 | P36: =ROUND('Barclays International Qrtly'!C11,0)+ROUND('Barclays International Qrtly'!E11,0)+ROUND('Barclays International Qrtly'!F11,0)+ROUND('Barclays International Qrtly'!G11,0) -> -9176 | Q36: =ROUND('Barclays International Qrtly'!H11,0)+ROUND('Barclays International Qrtly'!J11,0)+ROUND('Barclays International Qrtly'!K11,0)+ROUND('Barclays International Qrtly'!L11,0) -> -9230 | S36: =ROUND('Head Office Qrtly'!C10,0)+ROUND('Head Office Qrtly'!E10,0)+ROUND('Head Office Qrtly'!F10,0)+ROUND('Head Office Qrtly'!G10,0) -> -159 | T36: =ROUND('Head Office Qrtly'!H10,0)+ROUND('Head Office Qrtly'!J10,0)+ROUND('Head Office Qrtly'!K10,0)+ROUND('Head Office Qrtly'!L10,0) -> -221 | W36: =ROUND(G36,0)+ROUND(S36,0)+ROUND(P36,0)-ROUND(C36,0) -> 0 | Y36: =ROUND(H36,0)+ROUND(T36,0)+ROUND(Q36,0)-ROUND(D36,0) -> 0 | Z36: =ROUND(H36,0)+ROUND(T36,0)+ROUND(Q36,0)-ROUND(#REF!,0) -> #REF! | AC36: =P36-J36-M36 -> 0 | AE36: =Q36-K36-N36 -> 0 | AF36: =ROUND(N36,0)+ROUND(Z36,0)+ROUND(W36,0)-ROUND(#REF!,0) -> #REF!
B37: Bank Levy | C37: =ROUND('Group Qrtly'!C10,0)+ROUND('Group Qrtly'!E10,0)+ROUND('Group Qrtly'!F10,0)+ROUND('Group Qrtly'!G10,0) -> -226 | D37: =ROUND('Group Qrtly'!H10,0)+ROUND('Group Qrtly'!J10,0)+ROUND('Group Qrtly'!K10,0)+ROUND('Group Qrtly'!L10,0) -> -269 | G37: =ROUND('Barclays UK Qrtly'!C11,0)+ROUND('Barclays UK Qrtly'!E11,0)+ROUND('Barclays UK Qrtly'!F11,0)+ROUND('Barclays UK Qrtly'!G11,0) -> -41 | H37: =ROUND('Barclays UK Qrtly'!H11,0)+ROUND('Barclays UK Qrtly'!J11,0)+ROUND('Barclays UK Qrtly'!K11,0)+ROUND('Barclays UK Qrtly'!L11,0) -> -46 | J37: =ROUND('Barclays International Qrtly'!C68,0)+ROUND('Barclays International Qrtly'!E68,0)+ROUND('Barclays International Qrtly'!F68,0)+ROUND('Barclays International Qrtly'!G68,0) -> -156 | K37: =ROUND('Barclays International Qrtly'!H68,0)+ROUND('Barclays International Qrtly'!J68,0)+ROUND('Barclays International Qrtly'!K68,0)+ROUND('Barclays International Qrtly'!L68,0) -> -188 | M37: =ROUND('Barclays International Qrtly'!C109,0)+ROUND('Barclays International Qrtly'!E109,0)+ROUND('Barclays International Qrtly'!F109,0)+ROUND('Barclays International Qrtly'!G109,0) -> -18 | N37: =ROUND('Barclays International Qrtly'!H109,0)+ROUND('Barclays International Qrtly'!J109,0)+ROUND('Barclays International Qrtly'!K109,0)+ROUND('Barclays International Qrtly'!L109,0) -> -22 | P37: =ROUND('Barclays International Qrtly'!C12,0)+ROUND('Barclays International Qrtly'!E12,0)+ROUND('Barclays International Qrtly'!F12,0)+ROUND('Barclays International Qrtly'!G12,0) -> -174 | Q37: =ROUND('Barclays International Qrtly'!H12,0)+ROUND('Barclays International Qrtly'!J12,0)+ROUND('Barclays International Qrtly'!K12,0)+ROUND('Barclays International Qrtly'!L12,0) -> -210 | S37: =ROUND('Head Office Qrtly'!C11,0)+ROUND('Head Office Qrtly'!E11,0)+ROUND('Head Office Qrtly'!F11,0)+ROUND('Head Office Qrtly'!G11,0) -> -11 | T37: =ROUND('Head Office Qrtly'!H11,0)+ROUND('Head Office Qrtly'!J11,0)+ROUND('Head Office Qrtly'!K11,0)+ROUND('Head Office Qrtly'!L11,0) -> -13 | W37: =ROUND(G37,0)+ROUND(S37,0)+ROUND(P37,0)-ROUND(C37,0) -> 0 | AC37: =P37-J37-M37 -> 0 | AE37: =Q37-K37-N37 -> 0
B38: Litigation and conduct | C38: =ROUND('Group Qrtly'!C13,0)+ROUND('Group Qrtly'!E13,0)+ROUND('Group Qrtly'!F13,0)+ROUND('Group Qrtly'!G13,0) -> -1798 | D38: =ROUND('Group Qrtly'!H13,0)+ROUND('Group Qrtly'!J13,0)+ROUND('Group Qrtly'!K13,0)+ROUND('Group Qrtly'!L13,0) -> -307 | G38: =ROUND('Barclays UK Qrtly'!C13,0)+ROUND('Barclays UK Qrtly'!E13,0)+ROUND('Barclays UK Qrtly'!F13,0)+ROUND('Barclays UK Qrtly'!G13,0) -> -1584 | H38: =ROUND('Barclays UK Qrtly'!H13,0)+ROUND('Barclays UK Qrtly'!J13,0)+ROUND('Barclays UK Qrtly'!K13,0)+ROUND('Barclays UK Qrtly'!L13,0) -> -75 | J38: =ROUND('Barclays International Qrtly'!C70,0)+ROUND('Barclays International Qrtly'!E70,0)+ROUND('Barclays International Qrtly'!F70,0)+ROUND('Barclays International Qrtly'!G70,0) -> -90 | K38: =ROUND('Barclays International Qrtly'!H70,0)+ROUND('Barclays International Qrtly'!J70,0)+ROUND('Barclays International Qrtly'!K70,0)+ROUND('Barclays International Qrtly'!L70,0) -> #VALUE! | M38: =ROUND('Barclays International Qrtly'!C111,0)+ROUND('Barclays International Qrtly'!E111,0)+ROUND('Barclays International Qrtly'!F111,0)+ROUND('Barclays International Qrtly'!G111,0) -> -7 | N38: =ROUND('Barclays International Qrtly'!H111,0)+ROUND('Barclays International Qrtly'!J111,0)+ROUND('Barclays International Qrtly'!K111,0)+ROUND('Barclays International Qrtly'!L111,0) -> -57 | P38: =ROUND('Barclays International Qrtly'!C14,0)+ROUND('Barclays International Qrtly'!E14,0)+ROUND('Barclays International Qrtly'!F14,0)+ROUND('Barclays International Qrtly'!G14,0) -> -97 | Q38: =ROUND('Barclays International Qrtly'!H14,0)+ROUND('Barclays International Qrtly'!J14,0)+ROUND('Barclays International Qrtly'!K14,0)+ROUND('Barclays International Qrtly'!L14,0) -> -131 | S38: =ROUND('Head Office Qrtly'!C14,0)+ROUND('Head Office Qrtly'!E14,0)+ROUND('Head Office Qrtly'!F14,0)+ROUND('Head Office Qrtly'!G14,0) -> -117 | T38: =ROUND('Head Office Qrtly'!H14,0)+ROUND('Head Office Qrtly'!J14,0)+ROUND('Head Office Qrtly'!K14,0)+ROUND('Head Office Qrtly'!L14,0) -> -101 | W38: =ROUND(G38,0)+ROUND(S38,0)+ROUND(P38,0)-ROUND(C38,0) -> 0 | Y38: =ROUND(H38,0)+ROUND(T38,0)+ROUND(Q38,0)-ROUND(D38,0) -> 0 | Z38: =ROUND(H38,0)+ROUND(T38,0)+ROUND(Q38,0)-ROUND(#REF!,0) -> #REF! | AC38: =P38-J38-M38 -> 0 | AE38: =Q38-K38-N38 -> #VALUE! | AF38: =ROUND(N38,0)+ROUND(Z38,0)+ROUND(W38,0)-ROUND(#REF!,0) -> #REF!
B39: Total operating expenses | C39: =ROUND('Group Qrtly'!C14,0)+ROUND('Group Qrtly'!E14,0)+ROUND('Group Qrtly'!F14,0)+ROUND('Group Qrtly'!G14,0) -> -15379 | D39: =ROUND('Group Qrtly'!H14,0)+ROUND('Group Qrtly'!J14,0)+ROUND('Group Qrtly'!K14,0)+ROUND('Group Qrtly'!L14,0) -> -14236 | G39: =ROUND('Barclays UK Qrtly'!C14,0)+ROUND('Barclays UK Qrtly'!E14,0)+ROUND('Barclays UK Qrtly'!F14,0)+ROUND('Barclays UK Qrtly'!G14,0) -> -5645 | H39: =ROUND('Barclays UK Qrtly'!H14,0)+ROUND('Barclays UK Qrtly'!J14,0)+ROUND('Barclays UK Qrtly'!K14,0)+ROUND('Barclays UK Qrtly'!L14,0) -> -4190 | J39: =ROUND('Barclays International Qrtly'!C71,0)+ROUND('Barclays International Qrtly'!E71,0)+ROUND('Barclays International Qrtly'!F71,0)+ROUND('Barclays International Qrtly'!G71,0) -> -7199 | K39: =ROUND('Barclays International Qrtly'!H71,0)+ROUND('Barclays International Qrtly'!J71,0)+ROUND('Barclays International Qrtly'!K71,0)+ROUND('Barclays International Qrtly'!L71,0) -> -7201 | M39: =ROUND('Barclays International Qrtly'!C112,0)+ROUND('Barclays International Qrtly'!E112,0)+ROUND('Barclays International Qrtly'!F112,0)+ROUND('Barclays International Qrtly'!G112,0) -> -2248 | N39: =ROUND('Barclays International Qrtly'!H112,0)+ROUND('Barclays International Qrtly'!J112,0)+ROUND('Barclays International Qrtly'!K112,0)+ROUND('Barclays International Qrtly'!L112,0) -> -2370 | P39: =ROUND('Barclays International Qrtly'!C15,0)+ROUND('Barclays International Qrtly'!E15,0)+ROUND('Barclays International Qrtly'!F15,0)+ROUND('Barclays International Qrtly'!G15,0) -> -9447 | Q39: =ROUND('Barclays International Qrtly'!H15,0)+ROUND('Barclays International Qrtly'!J15,0)+ROUND('Barclays International Qrtly'!K15,0)+ROUND('Barclays International Qrtly'!L15,0) -> -9571 | S39: =ROUND('Head Office Qrtly'!C15,0)+ROUND('Head Office Qrtly'!E15,0)+ROUND('Head Office Qrtly'!F15,0)+ROUND('Head Office Qrtly'!G15,0) -> -287 | T39: =ROUND('Head Office Qrtly'!H15,0)+ROUND('Head Office Qrtly'!J15,0)+ROUND('Head Office Qrtly'!K15,0)+ROUND('Head Office Qrtly'!L15,0) -> -475 | W39: =ROUND(G39,0)+ROUND(S39,0)+ROUND(P39,0)-ROUND(C39,0) -> 0 | Y39: =ROUND(H39,0)+ROUND(T39,0)+ROUND(Q39,0)-ROUND(D39,0) -> 0 | Z39: =ROUND(H39,0)+ROUND(T39,0)+ROUND(Q39,0)-ROUND(#REF!,0) -> #REF! | AC39: =P39-J39-M39 -> 0 | AE39: =Q39-K39-N39 -> 0 | AF39: =ROUND(N39,0)+ROUND(Z39,0)+ROUND(W39,0)-ROUND(#REF!,0) -> #REF!
B40: Other net (expenses)/income | C40: =ROUND('Group Qrtly'!C15,0)+ROUND('Group Qrtly'!E15,0)+ROUND('Group Qrtly'!F15,0)+ROUND('Group Qrtly'!G15,0) -> 82 | D40: =ROUND('Group Qrtly'!H15,0)+ROUND('Group Qrtly'!J15,0)+ROUND('Group Qrtly'!K15,0)+ROUND('Group Qrtly'!L15,0) -> 47 | G40: =ROUND('Barclays UK Qrtly'!C15,0)+ROUND('Barclays UK Qrtly'!E15,0)+ROUND('Barclays UK Qrtly'!F15,0)+ROUND('Barclays UK Qrtly'!G15,0) -> #VALUE! | H40: =ROUND('Barclays UK Qrtly'!H15,0)+ROUND('Barclays UK Qrtly'!J15,0)+ROUND('Barclays UK Qrtly'!K15,0)+ROUND('Barclays UK Qrtly'!L15,0) -> 5 | J40: =ROUND('Barclays International Qrtly'!C72,0)+ROUND('Barclays International Qrtly'!E72,0)+ROUND('Barclays International Qrtly'!F72,0)+ROUND('Barclays International Qrtly'!G72,0) -> 16 | K40: =ROUND('Barclays International Qrtly'!H72,0)+ROUND('Barclays International Qrtly'!J72,0)+ROUND('Barclays International Qrtly'!K72,0)+ROUND('Barclays International Qrtly'!L72,0) -> 36 | M40: =ROUND('Barclays International Qrtly'!C113,0)+ROUND('Barclays International Qrtly'!E113,0)+ROUND('Barclays International Qrtly'!F113,0)+ROUND('Barclays International Qrtly'!G113,0) -> 41 | N40: =ROUND('Barclays International Qrtly'!H113,0)+ROUND('Barclays International Qrtly'!J113,0)+ROUND('Barclays International Qrtly'!K113,0)+ROUND('Barclays International Qrtly'!L113,0) -> 37 | P40: =ROUND('Barclays International Qrtly'!C16,0)+ROUND('Barclays International Qrtly'!E16,0)+ROUND('Barclays International Qrtly'!F16,0)+ROUND('Barclays International Qrtly'!G16,0) -> 57 | Q40: =ROUND('Barclays International Qrtly'!H16,0)+ROUND('Barclays International Qrtly'!J16,0)+ROUND('Barclays International Qrtly'!K16,0)+ROUND('Barclays International Qrtly'!L16,0) -> 73 | S40: =ROUND('Head Office Qrtly'!C16,0)+ROUND('Head Office Qrtly'!E16,0)+ROUND('Head Office Qrtly'!F16,0)+ROUND('Head Office Qrtly'!G16,0) -> 26 | T40: =ROUND('Head Office Qrtly'!H16,0)+ROUND('Head Office Qrtly'!J16,0)+ROUND('Head Office Qrtly'!K16,0)+ROUND('Head Office Qrtly'!L16,0) -> -31 | W40: =ROUND(G40,0)+ROUND(S40,0)+ROUND(P40,0)-ROUND(C40,0) -> #VALUE! | Y40: =ROUND(H40,0)+ROUND(T40,0)+ROUND(Q40,0)-ROUND(D40,0) -> 0 | AC40: =P40-J40-M40 -> 0 | AE40: =Q40-K40-N40 -> 0
B41: Profit/(loss) before tax | C41: =ROUND('Group Qrtly'!C16,0)+ROUND('Group Qrtly'!E16,0)+ROUND('Group Qrtly'!F16,0)+ROUND('Group Qrtly'!G16,0) -> 3787 | D41: =ROUND('Group Qrtly'!H16,0)+ROUND('Group Qrtly'!J16,0)+ROUND('Group Qrtly'!K16,0)+ROUND('Group Qrtly'!L16,0) -> 5213 | G41: =ROUND('Barclays UK Qrtly'!C16,0)+ROUND('Barclays UK Qrtly'!E16,0)+ROUND('Barclays UK Qrtly'!F16,0)+ROUND('Barclays UK Qrtly'!G16,0) -> 632 | H41: =ROUND('Barclays UK Qrtly'!H16,0)+ROUND('Barclays UK Qrtly'!J16,0)+ROUND('Barclays UK Qrtly'!K16,0)+ROUND('Barclays UK Qrtly'!L16,0) -> 2371 | J41: =ROUND('Barclays International Qrtly'!C73,0)+ROUND('Barclays International Qrtly'!E73,0)+ROUND('Barclays International Qrtly'!F73,0)+ROUND('Barclays International Qrtly'!G73,0) -> 3331 | K41: =ROUND('Barclays International Qrtly'!H73,0)+ROUND('Barclays International Qrtly'!J73,0)+ROUND('Barclays International Qrtly'!K73,0)+ROUND('Barclays International Qrtly'!L73,0) -> 2245 | M41: =ROUND('Barclays International Qrtly'!C114,0)+ROUND('Barclays International Qrtly'!E114,0)+ROUND('Barclays International Qrtly'!F114,0)+ROUND('Barclays International Qrtly'!G114,0) -> 491 | N41: =ROUND('Barclays International Qrtly'!H114,0)+ROUND('Barclays International Qrtly'!J114,0)+ROUND('Barclays International Qrtly'!K114,0)+ROUND('Barclays International Qrtly'!L114,0) -> 1235 | P41: =ROUND('Barclays International Qrtly'!C17,0)+ROUND('Barclays International Qrtly'!E17,0)+ROUND('Barclays International Qrtly'!F17,0)+ROUND('Barclays International Qrtly'!G17,0) -> 3822 | Q41: =ROUND('Barclays International Qrtly'!H17,0)+ROUND('Barclays International Qrtly'!J17,0)+ROUND('Barclays International Qrtly'!K17,0)+ROUND('Barclays International Qrtly'!L17,0) -> 3480 | S41: =ROUND('Head Office Qrtly'!C17,0)+ROUND('Head Office Qrtly'!E17,0)+ROUND('Head Office Qrtly'!F17,0)+ROUND('Head Office Qrtly'!G17,0) -> -667 | T41: =ROUND('Head Office Qrtly'!H17,0)+ROUND('Head Office Qrtly'!J17,0)+ROUND('Head Office Qrtly'!K17,0)+ROUND('Head Office Qrtly'!L17,0) -> -638 | W41: =ROUND(G41,0)+ROUND(S41,0)+ROUND(P41,0)-ROUND(C41,0) -> 0 | Y41: =ROUND(H41,0)+ROUND(T41,0)+ROUND(Q41,0)-ROUND(D41,0) -> 0 | Z41: =ROUND(H41,-2)+ROUND(T41,-2)+ROUND(Q41,-2)-ROUND(#REF!,-2) -> #REF! | AC41: =P41-J41-M41 -> 0 | AE41: =Q41-K41-N41 -> 0 | AF41: =ROUND(N41,-2)+ROUND(Z41,-2)+ROUND(W41,-2)-ROUND(#REF!,-2) -> #REF!
B42: Attributable profit/(loss)1 | C42: =ROUND('Group Qrtly'!C21,0)+ROUND('Group Qrtly'!E21,0)+ROUND('Group Qrtly'!F21,0)+ROUND('Group Qrtly'!G21,0) -> 2028 | D42: =ROUND('Group Qrtly'!H21,0)+ROUND('Group Qrtly'!J21,0)+ROUND('Group Qrtly'!K21,0)+ROUND('Group Qrtly'!L21,0) -> 3353 | G42: =ROUND('Barclays UK Qrtly'!C17,0)+ROUND('Barclays UK Qrtly'!E17,0)+ROUND('Barclays UK Qrtly'!F17,0)+ROUND('Barclays UK Qrtly'!G17,0) -> 34 | H42: =ROUND('Barclays UK Qrtly'!H17,0)+ROUND('Barclays UK Qrtly'!J17,0)+ROUND('Barclays UK Qrtly'!K17,0)+ROUND('Barclays UK Qrtly'!L17,0) -> 1646 | J42: =ROUND('Barclays International Qrtly'!C74,0)+ROUND('Barclays International Qrtly'!E74,0)+ROUND('Barclays International Qrtly'!F74,0)+ROUND('Barclays International Qrtly'!G74,0) -> 2218 | K42: =ROUND('Barclays International Qrtly'!H74,0)+ROUND('Barclays International Qrtly'!J74,0)+ROUND('Barclays International Qrtly'!K74,0)+ROUND('Barclays International Qrtly'!L74,0) -> 1529 | M42: =ROUND('Barclays International Qrtly'!C115,0)+ROUND('Barclays International Qrtly'!E115,0)+ROUND('Barclays International Qrtly'!F115,0)+ROUND('Barclays International Qrtly'!G115,0) -> 339 | N42: =ROUND('Barclays International Qrtly'!H115,0)+ROUND('Barclays International Qrtly'!J115,0)+ROUND('Barclays International Qrtly'!K115,0)+ROUND('Barclays International Qrtly'!L115,0) -> 851 | P42: =ROUND('Barclays International Qrtly'!C18,0)+ROUND('Barclays International Qrtly'!E18,0)+ROUND('Barclays International Qrtly'!F18,0)+ROUND('Barclays International Qrtly'!G18,0) -> 2557 | Q42: =ROUND('Barclays International Qrtly'!H18,0)+ROUND('Barclays International Qrtly'!J18,0)+ROUND('Barclays International Qrtly'!K18,0)+ROUND('Barclays International Qrtly'!L18,0) -> 2380 | S42: =ROUND('Head Office Qrtly'!C18,0)+ROUND('Head Office Qrtly'!E18,0)+ROUND('Head Office Qrtly'!F18,0)+ROUND('Head Office Qrtly'!G18,0) -> -563 | T42: =ROUND('Head Office Qrtly'!H18,0)+ROUND('Head Office Qrtly'!J18,0)+ROUND('Head Office Qrtly'!K18,0)+ROUND('Head Office Qrtly'!L18,0) -> -673 | W42: =ROUND(G42,0)+ROUND(S42,0)+ROUND(P42,0)-ROUND(C42,0) -> 0 | Y42: =ROUND(H42,0)+ROUND(T42,0)+ROUND(Q42,0)-ROUND(D42,0) -> 0 | AC42: =P42-J42-M42 -> 0 | AE42: =Q42-K42-N42 -> 0
B44: Average tangible shareholders' equity (£bn) | C44: =('Group Qrtly'!C25+'Group Qrtly'!E25+'Group Qrtly'!F25+'Group Qrtly'!G25)/4 -> 46995.033 | D44: =('Group Qrtly'!H25+'Group Qrtly'!J25+'Group Qrtly'!K25+'Group Qrtly'!L25)/4 -> 44423.09 | G44: =('Barclays UK Qrtly'!C29+'Barclays UK Qrtly'!E29+'Barclays UK Qrtly'!F29+'Barclays UK Qrtly'!G29)/4 -> 10374.568 | H44: =('Barclays UK Qrtly'!H29+'Barclays UK Qrtly'!J29+'Barclays UK Qrtly'!K29+'Barclays UK Qrtly'!L29)/4 -> 10167.484 | J44: =('Barclays International Qrtly'!C90+'Barclays International Qrtly'!E90+'Barclays International Qrtly'!F90+'Barclays International Qrtly'!G90)/4 -> 26433.913 | K44: =('Barclays International Qrtly'!H90+'Barclays International Qrtly'!J90+'Barclays International Qrtly'!K90+'Barclays International Qrtly'!L90)/4 -> 25844.157 | M44: =('Barclays International Qrtly'!C125+'Barclays International Qrtly'!E125+'Barclays International Qrtly'!F125+'Barclays International Qrtly'!G125)/4 -> 5227.6167 | N44: =('Barclays International Qrtly'!H125+'Barclays International Qrtly'!J125+'Barclays International Qrtly'!K125+'Barclays International Qrtly'!L125)/4 -> 5199.484 | P44: =('Barclays International Qrtly'!C36+'Barclays International Qrtly'!E36+'Barclays International Qrtly'!F36+'Barclays International Qrtly'!G36)/4 -> 31624.77 | Q44: =('Barclays International Qrtly'!H36+'Barclays International Qrtly'!J36+'Barclays International Qrtly'!K36+'Barclays International Qrtly'!L36)/4 -> 31068.641 | S44: =('Head Office Qrtly'!C26+'Head Office Qrtly'!E26+'Head Office Qrtly'!F26+'Head Office Qrtly'!G26)/4 -> 5006.9443 | T44: =('Head Office Qrtly'!H26+'Head Office Qrtly'!J26+'Head Office Qrtly'!K26+'Head Office Qrtly'!L26)/4 -> 3157.1485 | W44: =ROUND(G44,-2)+ROUND(S44,-2)+ROUND(P44,-2)-ROUND(C44,-2) -> 0 | Y44: =ROUND(H44,-1)+ROUND(T44,-1)+ROUND(Q44,-1)-ROUND(D44,-1) -> -20 | AC44: =P44-J44-M44 -> -36.758971 | AE44: =Q44-K44-N44 -> 25
B45: Basic earnings/(loss) per share | C45: ='Group Qrtly'!C28+'Group Qrtly'!E28+'Group Qrtly'!F28+'Group Qrtly'!G28 -> 11.770129
B47: Profit/(loss) before tax ex L&C | C47: =ROUND('Group Qrtly'!C31,0)+ROUND('Group Qrtly'!E31,0)+ROUND('Group Qrtly'!F31,0)+ROUND('Group Qrtly'!G31,0) -> 5585 | D47: =ROUND('Group Qrtly'!H31,0)+ROUND('Group Qrtly'!J31,0)+ROUND('Group Qrtly'!K31,0)+ROUND('Group Qrtly'!L31,0) -> 5520 | G47: =ROUND('Barclays UK Qrtly'!C35,0)+ROUND('Barclays UK Qrtly'!E35,0)+ROUND('Barclays UK Qrtly'!F35,0)+ROUND('Barclays UK Qrtly'!G35,0) -> 2216 | H47: =ROUND('Barclays UK Qrtly'!H35,0)+ROUND('Barclays UK Qrtly'!J35,0)+ROUND('Barclays UK Qrtly'!K35,0)+ROUND('Barclays UK Qrtly'!L35,0) -> 2446 | J47: =ROUND('Barclays International Qrtly'!C94,0)+ROUND('Barclays International Qrtly'!E94,0)+ROUND('Barclays International Qrtly'!F94,0)+ROUND('Barclays International Qrtly'!G94,0) -> 3421 | K47: =ROUND('Barclays International Qrtly'!H94,0)+ROUND('Barclays International Qrtly'!J94,0)+ROUND('Barclays International Qrtly'!K94,0)+ROUND('Barclays International Qrtly'!L94,0) -> 2319 | M47: =ROUND('Barclays International Qrtly'!C130,0)+ROUND('Barclays International Qrtly'!E130,0)+ROUND('Barclays International Qrtly'!F130,0)+ROUND('Barclays International Qrtly'!G130,0) -> 498 | N47: =ROUND('Barclays International Qrtly'!H130,0)+ROUND('Barclays International Qrtly'!J130,0)+ROUND('Barclays International Qrtly'!K130,0)+ROUND('Barclays International Qrtly'!L130,0) -> 1292 | P47: =ROUND('Barclays International Qrtly'!C42,0)+ROUND('Barclays International Qrtly'!E42,0)+ROUND('Barclays International Qrtly'!F42,0)+ROUND('Barclays International Qrtly'!G42,0) -> 3919 | Q47: =ROUND('Barclays International Qrtly'!H42,0)+ROUND('Barclays International Qrtly'!J42,0)+ROUND('Barclays International Qrtly'!K42,0)+ROUND('Barclays International Qrtly'!L42,0) -> 3611 | S47: =ROUND('Head Office Qrtly'!C29,0)+ROUND('Head Office Qrtly'!E29,0)+ROUND('Head Office Qrtly'!F29,0)+ROUND('Head Office Qrtly'!G29,0) -> -550 | T47: =ROUND('Head Office Qrtly'!H29,0)+ROUND('Head Office Qrtly'!J29,0)+ROUND('Head Office Qrtly'!K29,0)+ROUND('Head Office Qrtly'!L29,0) -> -537 | W47: =ROUND(G47,0)+ROUND(S47,0)+ROUND(P47,0)-ROUND(C47,0) -> 0 | Y47: =ROUND(H47,0)+ROUND(T47,0)+ROUND(Q47,0)-ROUND(D47,0) -> 0 | AC47: =P47-J47-M47 -> 0 | AE47: =Q47-K47-N47 -> 0
B48: Attributable profit/(loss) ex L&C | C48: =ROUND('Group Qrtly'!C32,0)+ROUND('Group Qrtly'!E32,0)+ROUND('Group Qrtly'!F32,0)+ROUND('Group Qrtly'!G32,0) -> 3714 | D48: =ROUND('Group Qrtly'!H32,0)+ROUND('Group Qrtly'!J32,0)+ROUND('Group Qrtly'!K32,0)+ROUND('Group Qrtly'!L32,0) -> 3605 | G48: =ROUND('Barclays UK Qrtly'!C36,0)+ROUND('Barclays UK Qrtly'!E36,0)+ROUND('Barclays UK Qrtly'!F36,0)+ROUND('Barclays UK Qrtly'!G36,0) -> 1567 | H48: =ROUND('Barclays UK Qrtly'!H36,0)+ROUND('Barclays UK Qrtly'!J36,0)+ROUND('Barclays UK Qrtly'!K36,0)+ROUND('Barclays UK Qrtly'!L36,0) -> 1709 | J48: =ROUND('Barclays International Qrtly'!C95,0)+ROUND('Barclays International Qrtly'!E95,0)+ROUND('Barclays International Qrtly'!F95,0)+ROUND('Barclays International Qrtly'!G95,0) -> 2286 | K48: =ROUND('Barclays International Qrtly'!H95,0)+ROUND('Barclays International Qrtly'!J95,0)+ROUND('Barclays International Qrtly'!K95,0)+ROUND('Barclays International Qrtly'!L95,0) -> 1597 | M48: =ROUND('Barclays International Qrtly'!C131,0)+ROUND('Barclays International Qrtly'!E131,0)+ROUND('Barclays International Qrtly'!F131,0)+ROUND('Barclays International Qrtly'!G131,0) -> 345 | N48: =ROUND('Barclays International Qrtly'!H131,0)+ROUND('Barclays International Qrtly'!J131,0)+ROUND('Barclays International Qrtly'!K131,0)+ROUND('Barclays International Qrtly'!L131,0) -> 893 | P48: =ROUND('Barclays International Qrtly'!C43,0)+ROUND('Barclays International Qrtly'!E43,0)+ROUND('Barclays International Qrtly'!F43,0)+ROUND('Barclays International Qrtly'!G43,0) -> 2631 | Q48: =ROUND('Barclays International Qrtly'!H43,0)+ROUND('Barclays International Qrtly'!J43,0)+ROUND('Barclays International Qrtly'!K43,0)+ROUND('Barclays International Qrtly'!L43,0) -> 2490 | S48: =ROUND('Head Office Qrtly'!C30,0)+ROUND('Head Office Qrtly'!E30,0)+ROUND('Head Office Qrtly'!F30,0)+ROUND('Head Office Qrtly'!G30,0) -> -484 | T48: =ROUND('Head Office Qrtly'!H30,0)+ROUND('Head Office Qrtly'!J30,0)+ROUND('Head Office Qrtly'!K30,0)+ROUND('Head Office Qrtly'!L30,0) -> -594 | W48: =ROUND(G76,0)+ROUND(S76,0)+ROUND(P76,0)-ROUND(C76,0) -> 5283 | Y48: =ROUND(H76,0)+ROUND(T76,0)+ROUND(Q76,0)-ROUND(D76,0) -> 4157 | Z48: =ROUND(H76,-3)+ROUND(T76,-3)+ROUND(Q76,-3)-ROUND(#REF!,-3) -> #REF! | AC48: =P48-J48-M48 -> 0 | AE48: =Q48-K48-N48 -> 0 | AF48: =ROUND(N76,-3)+ROUND(Z76,-3)+ROUND(W76,-3)-ROUND(#REF!,-3) -> #REF!
B49: Post tax L&C impact | C49: =ROUND('Group performance measures excl'!B21,0)+ROUND('Group performance measures excl'!D21,0)+ROUND('Group performance measures excl'!E21,0)+ROUND('Group performance measures excl'!F21,0) -> 1686 | D49: =ROUND('Group performance measures excl'!G21,0)+ROUND('Group performance measures excl'!I21,0)+ROUND('Group performance measures excl'!J21,0)+ROUND('Group performance measures excl'!K21,0) -> 252 | G49: =ROUND('BUK performance measures excl'!B19,0)+ROUND('BUK performance measures excl'!D19,0)+ROUND('BUK performance measures excl'!E19,0)+ROUND('BUK performance measures excl'!F19,0) -> 1533 | H49: =ROUND('BUK performance measures excl'!G19,0)+ROUND('BUK performance measures excl'!I19,0)+ROUND('BUK performance measures excl'!J19,0)+ROUND('BUK performance measures excl'!K19,0) -> 63 | J49: =ROUND('BI performance measures excl'!B48,0)+ROUND('BI performance measures excl'!D48,0)+ROUND('BI performance measures excl'!E48,0)+ROUND('BI performance measures excl'!F48,0) -> 68 | K49: =ROUND('BI performance measures excl'!G48,0)+ROUND('BI performance measures excl'!I48,0)+ROUND('BI performance measures excl'!J48,0)+ROUND('BI performance measures excl'!K48,0) -> 68 | M49: =ROUND('BI performance measures excl'!B77,0)+ROUND('BI performance measures excl'!D77,0)+ROUND('BI performance measures excl'!E77,0)+ROUND('BI performance measures excl'!F77,0) -> 6 | N49: =ROUND('BI performance measures excl'!G77,0)+ROUND('BI performance measures excl'!I77,0)+ROUND('BI performance measures excl'!J77,0)+ROUND('BI performance measures excl'!K77,0) -> 42 | P49: =ROUND('BI performance measures excl'!B19,0)+ROUND('BI performance measures excl'!D19,0)+ROUND('BI performance measures excl'!E19,0)+ROUND('BI performance measures excl'!F19,0) -> 74 | Q49: =ROUND('BI performance measures excl'!G19,0)+ROUND('BI performance measures excl'!I19,0)+ROUND('BI performance measures excl'!J19,0)+ROUND('BI performance measures excl'!K19,0) -> 110 | S49: =ROUND('HO performance measures excl'!B10,0)+ROUND('HO performance measures excl'!D10,0)+ROUND('HO performance measures excl'!E10,0)+ROUND('HO performance measures excl'!F10,0) -> 79 | T49: =ROUND('HO performance measures excl'!G10,0)+ROUND('HO performance measures excl'!I10,0)+ROUND('HO performance measures excl'!J10,0)+ROUND('HO performance measures excl'!K10,0) -> 79 | W49: =ROUND(G49,0)+ROUND(S49,0)+ROUND(P49,0)-ROUND(C49,0) -> 0 | Y49: =ROUND(H49,0)+ROUND(T49,0)+ROUND(Q49,0)-ROUND(D49,0) -> 0 | AC49: =P49-J49-M49 -> 0 | AE49: =Q49-K49-N49 -> 0
Z50: =ROUND(H50,-3)+ROUND(T50,-3)+ROUND(Q50,-3)-ROUND(#REF!,-3) -> #REF! | AF50: =ROUND(N50,-3)+ROUND(Z50,-3)+ROUND(W50,-3)-ROUND(#REF!,-3) -> #REF!
B51: Total assets | C51: ='Group Qrtly'!C38 -> 1444297 | D51: ='Group Qrtly'!H38 -> 1193543 | G51: ='Barclays UK Qrtly'!C21 -> 267542 | H51: ='Barclays UK Qrtly'!H21 -> 253086 | J51: ='Barclays International Qrtly'!C83 -> 1082486 | K51: ='Barclays International Qrtly'!H83 -> 838100 | M51: ='Barclays International Qrtly'!C119 -> 70715 | N51: ='Barclays International Qrtly'!H119 -> 80900 | P51: ='Barclays International Qrtly'!C27 -> 1153201 | Q51: ='Barclays International Qrtly'!H27 -> 918950 | S51: ='Head Office Qrtly'!C21 -> 23554 | T51: ='Head Office Qrtly'!H21 -> 21407 | W51: =ROUND(G51,-2)+ROUND(S51,-2)+ROUND(P51,-2)-ROUND(C51,-2) -> 0 | Y51: =ROUND(H51,-2)+ROUND(T51,-2)+ROUND(Q51,-2)-ROUND(D51,-2) -> 0 | AC51: =P51-J51-M51 -> 0 | AE51: =Q51-K51-N51 -> -50
...

Sheet Group PH
B1: Barclays Group results
B2: for the three months ended | C2: 31.03.20 | D2: 31.03.19
C3: £m | D3: £m | E3: % Change
B4: Total income | C4: 6283 | D4: 5252 | E4: 19.630617
B5: Credit impairment charges | C5: -2115 | D5: -448
B6: Net operating income | C6: 4168 | D6: 4804 | E6: -13.238968
B7: Operating expenses | C7: -3253 | D7: -3257 | E7: -
B8: Litigation and conduct | C8: -10.340854 | D8: -61 | E8: 83.606557
B9: Total operating expenses | C9: -3263 | D9: -3318 | E9: 1.6576251
B10: Other net income/(expenses) | C10: 8 | D10: -3
B11: Profit before tax | C11: 913 | D11: 1483 | E11: -38.435604
B12: Tax charge | C12: -71 | D12: -248 | E12: 71.370968
B13: Profit after tax | C13: 842 | D13: 1235 | E13: -31.821862
B14: Non-controlling interests | C14: -16 | D14: -17 | E14: 5.8823529
B15: Other equity instrument holders | C15: -221 | D15: -180 | E15: -22.777778
B16: Attributable profit | C16: 605 | D16: 1038 | E16: -41.714836
B18: Performance measures
B19: Return on average tangible shareholders' equity | C19: 0.051 | D19: 0.092
B20: Average tangible shareholders' equity (£bn) | C20: 46994.626 | D20: 45200
B21: Cost: income ratio | C21: 0.52 | D21: 0.63
B22: Loan loss rate (bps) | C22: 222.58505 | D22: 54
B23: Basic earnings per share | C23: 3.5015357 | D23: 6.1
B25: Performance measures excluding litigation and conduct
B26: Profit before tax | C26: 923.34085 | D26: 1544 | E26: -40.220207
B27: Attributable profit | C27: 604.40094 | D27: 1084 | E27: -44.280443
B28: Return on average tangible shareholders' equity | C28: 0.051 | D28: 0.096
B29: Cost: income ratio | C29: 0.52 | D29: 0.62
B30: Basic earnings per share | C30: 3.4980685 | D30: 6.3
C32: As at 31.03.20 | D32: As at 31.12.19 | E32: As at 31.03.19
B33: Balance sheet and capital management | C33: £bn | D33: £bn | E33: £bn
B34: Tangible net asset value per share | C34: 284.38013 | D34: 262.31927 | E34: 266
B35: Common equity tier 1 ratio | C35: 0.131 | D35: 0.138 | E35: 0.13
B36: Common equity tier 1 capital | C36: 42484 | D36: 40813.416 | E36: 41400
B37: Risk weighted assets | C37: 325631 | D37: 295131.09 | E37: 319700
B38: Average UK leverage ratio | C38: 0.045 | D38: 0.045 | E38: 0.046
B39: UK leverage ratio | C39: 0.045 | D39: 0.051 | E39: 0.049
B41: Funding and liquidity
B42: Group liquidity pool (£bn) | C42: 237000 | D42: 211000 | E42: 232000
B43: Liquidity coverage ratio | C43: 1.55 | D43: 1.6 | E43: 1.6
B44: Loan: deposit ratio | C44: 0.79 | D44: 0.82 | E44: 0.8

Sheet Barclays UK YTD
B2: Barclays UK | C2: Year ended | D2: Year ended
C3: 31.12.19 | D3: 31.12.18
B4: Income statement information | C4: £m | D4: £m | E4: % Change | H4: % Check | L4: =CQtr&" YTD" -> #REF! | M4: =PPPPQtr&" YTD" -> #REF!
B5: Net interest income | C5: 5888 | D5: 6028 | E5: -2.322495 | H5: =IFERROR(ROUND(IF(C5>0,100*(ROUND(C5,0)-ROUND(D5,0))/ROUND(D5,0),-100*(ROUND(C5,0)-ROUND(D5,0))/ROUND(D5,0)),0)-ROUND(E5,0),0) -> 0 | J5: Casting down check | L5: Check to Appendix
B6: Net fee, commission and other income | C6: 1465 | D6: 1355 | E6: 8.1180812 | H6: =IFERROR(ROUND(IF(C6>0,100*(ROUND(C6,0)-ROUND(D6,0))/ROUND(D6,0),-100*(ROUND(C6,0)-ROUND(D6,0))/ROUND(D6,0)),0)-ROUND(E6,0),0) -> 0 | J6: =CQtr&" YTD" -> #REF! | K6: =PPPPQtr&" YTD" -> #REF!
B7: Total income | C7: 7353 | D7: 7383 | E7: - | H7: =IFERROR(ROUND(IF(C7>0,100*(ROUND(C7,0)-ROUND(D7,0))/ROUND(D7,0),-100*(ROUND(C7,0)-ROUND(D7,0))/ROUND(D7,0)),0)-ROUND(E7,0),0) -> 0 | J7: =ROUND(C5,0)+ROUND(C6,0)-ROUND(C7,0) -> 0 | K7: =ROUND(D5,0)+ROUND(D6,0)-ROUND(D7,0) -> 0 | L7: =C7-'CYYTD performance measures excl'!B10 -> 0 | M7: =D7-'PYYTD performance measures'!B10 -> 0
B8: Credit impairment charges | C8: -712 | D8: -826 | E8: 13.801453 | H8: =IFERROR(ROUND(IF(C8>0,100*(ROUND(C8,0)-ROUND(D8,0))/ROUND(D8,0),-100*(ROUND(C8,0)-ROUND(D8,0))/ROUND(D8,0)),0)-ROUND(E8,0),0) -> 0
B9: Net operating income | C9: 6641 | D9: 6557 | E9: 1.2810737 | H9: =IFERROR(ROUND(IF(C9>0,100*(ROUND(C9,0)-ROUND(D9,0))/ROUND(D9,0),-100*(ROUND(C9,0)-ROUND(D9,0))/ROUND(D9,0)),0)-ROUND(E9,0),0) -> 0
B10: Operating costs | C10: -3995.6945 | D10: -4075 | E10: 1.9386503 | H10: =IFERROR(ROUND(IF(C10>0,100*(ROUND(C10,0)-ROUND(D10,0))/ROUND(D10,0),-100*(ROUND(C10,0)-ROUND(D10,0))/ROUND(D10,0)),0)-ROUND(E10,0),0) -> 0 | J10: =ROUND(C7,0)+ROUND(C8,0)-ROUND(C9,0) -> 0 | K10: =ROUND(D7,0)+ROUND(D8,0)-ROUND(D9,0) -> 0 | L10: =ROUND(C10,0)+ROUND(C11,0)-ROUND('CYYTD performance measures excl'!B8,0) -> 0 | M10: =D10+D11-'PYYTD performance measures'!B8 -> 0
B11: UK bank levy | C11: -41 | D11: -46 | E11: 10.869565 | H11: =IFERROR(ROUND(IF(C11>0,100*(ROUND(C11,0)-ROUND(D11,0))/ROUND(D11,0),-100*(ROUND(C11,0)-ROUND(D11,0))/ROUND(D11,0)),0)-ROUND(E11,0),0) -> 0
B12: Operating expenses | C12: -4036.6945 | D12: -4121 | E12: 2.0383402 | H12: =IFERROR(ROUND(IF(C12>0,100*(ROUND(C12,0)-ROUND(D12,0))/ROUND(D12,0),-100*(ROUND(C12,0)-ROUND(D12,0))/ROUND(D12,0)),0)-ROUND(E12,0),0) -> 0 | J12: =ROUND(C10,0)+ROUND(C11,0)-ROUND(C12,0) -> 0 | K12: =ROUND(D10,0)+ROUND(D11,0)-ROUND(D12,0) -> 0 | L12: =ROUND(C12,0)-ROUND('CYYTD performance measures excl'!B8,0) -> 0 | M12: =ROUND(D12,0)-'PYYTD performance measures'!B8 -> 0
B13: Litigation and conduct | C13: -1582.3055 | D13: -483 | H13: =IFERROR(ROUND(IF(C13>0,100*(ROUND(C13,0)-ROUND(D13,0))/ROUND(D13,0),-100*(ROUND(C13,0)-ROUND(D13,0))/ROUND(D13,0)),0)-ROUND(E13,0),0) -> 0
B14: Total operating expenses | C14: -5619 | D14: -4604 | E14: -22.046047 | H14: =IFERROR(ROUND(IF(C14>0,100*(ROUND(C14,0)-ROUND(D14,0))/ROUND(D14,0),-100*(ROUND(C14,0)-ROUND(D14,0))/ROUND(D14,0)),0)-ROUND(E14,0),0) -> 0 | J14: =+ROUND(C10,0)-ROUND(C14,0)+ROUND(C13,0)+ROUND(C11,0) -> 0 | K14: =+ROUND(D10,0)-ROUND(D14,0)+ROUND(D13,0)+ROUND(D11,0) -> 0 | L14: =C14-'CYYTD performance measures excl'!B6 -> 0 | M14: =D14-'PYYTD performance measures'!B6 -> 0
B15: Other net income | C15: - | D15: 3 | H15: =IFERROR(ROUND(IF(C15>0,100*(ROUND(C15,0)-ROUND(D15,0))/ROUND(D15,0),-100*(ROUND(C15,0)-ROUND(D15,0))/ROUND(D15,0)),0)-ROUND(E15,0),0) -> 0
B16: Profit before tax | C16: 1022 | D16: 1956 | E16: -47.750511 | H16: =IFERROR(ROUND(IF(C16>0,100*(ROUND(C16,0)-ROUND(D16,0))/ROUND(D16,0),-100*(ROUND(C16,0)-ROUND(D16,0))/ROUND(D16,0)),0)-ROUND(E16,0),0) -> 0 | J16: =ROUND(C9,0)+ROUND(C10,0)+ROUND(C15,0)-ROUND(C16,0)+ROUND(C13,0)+ROUND(C11,0) -> #VALUE! | K16: =ROUND(D9,0)+ROUND(D10,0)+ROUND(D15,0)-ROUND(D16,0)+ROUND(D13,0)+ROUND(D11,0) -> 0 | L16: =C16-'CYYTD performance measures excl'!B15 -> 0 | M16: =D16-'PYYTD performance measures'!B15 -> 0
B17: Attributable profit1 | C17: 281 | D17: 1198 | E17: -76.54424 | H17: =IFERROR(ROUND(IF(C17>0,100*(ROUND(C17,0)-ROUND(D17,0))/ROUND(D17,0),-100*(ROUND(C17,0)-ROUND(D17,0))/ROUND(D17,0)),0)-ROUND(E17,0),0) -> 0 | K17: AP | L17: =C17-'CYYTD performance measures excl'!B20 -> 0 | M17: =D17-'PYYTD performance measures'!B20 -> 0
B19: Balance sheet information | C19: £bn | D19: £bn | H19: Consistency with quarterlies check | L19: =CQtr -> #REF! | M19: Q418 | N19: Q318
B20: Loans and advances to customers at amortised cost | C20: 193700 | D20: 187600 | G20: Loans and advances to customers at amortised cost | H20: =ROUND(C20,-2)-ROUND(L20,-2) -> -2000 | I20: =ROUND(D20,-2)-ROUND(M20,-2) -> 100 | L20: ='Barclays UK Qrtly'!C20 -> 195700 | M20: ='Barclays UK Qrtly'!H20 -> 187500 | N20: ='Barclays UK Qrtly'!J20 -> 187600
B21: Total assets | C21: 257776 | D21: 249700 | G21: Total assets | H21: =ROUND(C21,-2)-ROUND(L21,-2) -> -9700 | I21: =ROUND(D21,-2)-ROUND(M21,-2) -> -3400 | L21: ='Barclays UK Qrtly'!C21 -> 267542 | M21: ='Barclays UK Qrtly'!H21 -> 253086 | N21: ='Barclays UK Qrtly'!J21 -> 249669
B22: Customer deposits at amortised cost | C22: 205477.24 | D22: 197300 | G22: Customer deposits at amortised cost | H22: =ROUND(C22,-2)-ROUND(L22,-2) -> -2000 | I22: =ROUND(D22,-2)-ROUND(M22,-2) -> 0 | L22: ='Barclays UK Qrtly'!C22 -> 207489.79 | M22: ='Barclays UK Qrtly'!H22 -> 197284.41 | N22: ='Barclays UK Qrtly'!J22 -> 197279.46
B23: Loan: deposit ratio | C23: 0.96 | D23: 0.96 | G23: Loan: deposit ratio | H23: =C23-L23 -> 0 | I23: =D23-M23 -> 0 | L23: ='Barclays UK Qrtly'!C23 -> 0.96 | M23: ='Barclays UK Qrtly'!H23 -> 0.96 | N23: ='Barclays UK Qrtly'!J23 -> 0.96
B24: Risk weighted assets | C24: 74900.809 | D24: 75200 | G24: Risk weighted assets | H24: =ROUND(C24,-2)-ROUND(L24,-2) -> -2800 | I24: =ROUND(D24,-2)-ROUND(M24,-2) -> -1400 | L24: ='Barclays UK Qrtly'!C24 -> 77678 | M24: ='Barclays UK Qrtly'!H24 -> 76558.949 | N24: ='Barclays UK Qrtly'!J24 -> 75181
B25: Period end allocated tangible equity | C25: 10253.792 | D25: 10200 | G25: Period end allocated tangible equity | H25: =ROUND(C25,-2)-ROUND(L25,-2) -> -300 | I25: =ROUND(D25,-2)-ROUND(M25,-2) -> -300 | L25: ='Barclays UK Qrtly'!C25 -> 10645.223 | M25: ='Barclays UK Qrtly'!H25 -> 10466.112 | N25: ='Barclays UK Qrtly'!J25 -> 10201.511
B27: Key facts
B28: Average loan to value of mortgage portfolio2 | C28: 0.51 | D28: 0.49
B29: Average loan to value of new mortgage lending2 | C29: 0.68 | D29: 0.65
B30: Number of branches | C30: 963 | D30: 1058
B31: Mobile banking active customers | C31: 8.4 | D31: 7.3m
B32: 30 day arrears rate - Barclaycard Consumer UK | C32: 0.017 | D32: 0.018
B34: Performance measures
B35: Return on average allocated tangible equity | C35: 0.027 | D35: 0.119
B36: Average allocated tangible equity (£bn) | C36: 10333.198 | D36: 10000 | H36: ROTE check
